====================*************
===============
-------------
1480829353.86
-------------
Traceback (most recent call last):
  File "asynchronoussgd_distributed_optimized.py", line 151, in <module>
    sess.run(assign_op)
  File "/usr/local/lib/python2.7/dist-packages/tensorflow/python/client/session.py", line 717, in run
    run_metadata_ptr)
  File "/usr/local/lib/python2.7/dist-packages/tensorflow/python/client/session.py", line 915, in _run
    feed_dict_string, options, run_metadata)
  File "/usr/local/lib/python2.7/dist-packages/tensorflow/python/client/session.py", line 965, in _do_run
    target_list, options, run_metadata)
  File "/usr/local/lib/python2.7/dist-packages/tensorflow/python/client/session.py", line 985, in _do_call
    raise type(e)(node_def, op, message)
tensorflow.python.framework.errors.FailedPreconditionError: Attempting to use uninitialized value model
	 [[Node: model/read = Identity[T=DT_FLOAT, _class=["loc:@model"], _device="/job:worker/replica:0/task:0/cpu:0"](model)]]

Caused by op u'model/read', defined at:
  File "asynchronoussgd_distributed_optimized.py", line 80, in <module>
    w = tf.Variable(tf.random_uniform([num_features, 1]), name="model")
  File "/usr/local/lib/python2.7/dist-packages/tensorflow/python/ops/variables.py", line 215, in __init__
    dtype=dtype)
  File "/usr/local/lib/python2.7/dist-packages/tensorflow/python/ops/variables.py", line 327, in _init_from_args
    self._snapshot = array_ops.identity(self._variable, name="read")
  File "/usr/local/lib/python2.7/dist-packages/tensorflow/python/ops/gen_array_ops.py", line 1128, in identity
    result = _op_def_lib.apply_op("Identity", input=input, name=name)
  File "/usr/local/lib/python2.7/dist-packages/tensorflow/python/framework/op_def_library.py", line 749, in apply_op
    op_def=op_def)
  File "/usr/local/lib/python2.7/dist-packages/tensorflow/python/framework/ops.py", line 2380, in create_op
    original_op=self._default_original_op, op_def=op_def)
  File "/usr/local/lib/python2.7/dist-packages/tensorflow/python/framework/ops.py", line 1298, in __init__
    self._traceback = _extract_stack()

FailedPreconditionError (see above for traceback): Attempting to use uninitialized value model
	 [[Node: model/read = Identity[T=DT_FLOAT, _class=["loc:@model"], _device="/job:worker/replica:0/task:0/cpu:0"](model)]]

