====================*************
===============
-------------
1480829353.48
-------------
Traceback (most recent call last):
  File "asynchronoussgd_distributed_optimized.py", line 151, in <module>
    sess.run(assign_op)
  File "/usr/local/lib/python2.7/dist-packages/tensorflow/python/client/session.py", line 717, in run
    run_metadata_ptr)
  File "/usr/local/lib/python2.7/dist-packages/tensorflow/python/client/session.py", line 915, in _run
    feed_dict_string, options, run_metadata)
  File "/usr/local/lib/python2.7/dist-packages/tensorflow/python/client/session.py", line 965, in _do_run
    target_list, options, run_metadata)
  File "/usr/local/lib/python2.7/dist-packages/tensorflow/python/client/session.py", line 985, in _do_call
    raise type(e)(node_def, op, message)
tensorflow.python.framework.errors.UnavailableError: {"created":"@1480829353.862599057","description":"OS Error","errno":104,"file":"external/grpc/src/core/lib/iomgr/tcp_posix.c","file_line":229,"grpc_status":14,"os_error":"Connection reset by peer","syscall":"recvmsg"}
